2021-01-18 09:11:43,839 ERROR: Exception on /edit_profile [POST] [in d:\ti\python\workspace\microblog\microblog_env\lib\site-packages\flask\app.py:1891]
Traceback (most recent call last):
  File "d:\ti\python\workspace\microblog\microblog_env\lib\site-packages\sqlalchemy\engine\base.py", line 1276, in _execute_context
    self.dialect.do_execute(
  File "d:\ti\python\workspace\microblog\microblog_env\lib\site-packages\sqlalchemy\engine\default.py", line 609, in do_execute
    cursor.execute(statement, parameters)
sqlite3.IntegrityError: UNIQUE constraint failed: user.username

The above exception was the direct cause of the following exception:

Traceback (most recent call last):
  File "d:\ti\python\workspace\microblog\microblog_env\lib\site-packages\flask\app.py", line 2447, in wsgi_app
    response = self.full_dispatch_request()
  File "d:\ti\python\workspace\microblog\microblog_env\lib\site-packages\flask\app.py", line 1952, in full_dispatch_request
    rv = self.handle_user_exception(e)
  File "d:\ti\python\workspace\microblog\microblog_env\lib\site-packages\flask\app.py", line 1821, in handle_user_exception
    reraise(exc_type, exc_value, tb)
  File "d:\ti\python\workspace\microblog\microblog_env\lib\site-packages\flask\_compat.py", line 39, in reraise
    raise value
  File "d:\ti\python\workspace\microblog\microblog_env\lib\site-packages\flask\app.py", line 1950, in full_dispatch_request
    rv = self.dispatch_request()
  File "d:\ti\python\workspace\microblog\microblog_env\lib\site-packages\flask\app.py", line 1936, in dispatch_request
    return self.view_functions[rule.endpoint](**req.view_args)
  File "D:\TI\Python\Workspace\microblog\app\routes.py", line 95, in edit_profile
    db.session.commit()
  File "d:\ti\python\workspace\microblog\microblog_env\lib\site-packages\sqlalchemy\orm\scoping.py", line 163, in do
    return getattr(self.registry(), name)(*args, **kwargs)
  File "d:\ti\python\workspace\microblog\microblog_env\lib\site-packages\sqlalchemy\orm\session.py", line 1046, in commit
    self.transaction.commit()
  File "d:\ti\python\workspace\microblog\microblog_env\lib\site-packages\sqlalchemy\orm\session.py", line 504, in commit
    self._prepare_impl()
  File "d:\ti\python\workspace\microblog\microblog_env\lib\site-packages\sqlalchemy\orm\session.py", line 483, in _prepare_impl
    self.session.flush()
  File "d:\ti\python\workspace\microblog\microblog_env\lib\site-packages\sqlalchemy\orm\session.py", line 2540, in flush
    self._flush(objects)
  File "d:\ti\python\workspace\microblog\microblog_env\lib\site-packages\sqlalchemy\orm\session.py", line 2682, in _flush
    transaction.rollback(_capture_exception=True)
  File "d:\ti\python\workspace\microblog\microblog_env\lib\site-packages\sqlalchemy\util\langhelpers.py", line 68, in __exit__
    compat.raise_(
  File "d:\ti\python\workspace\microblog\microblog_env\lib\site-packages\sqlalchemy\util\compat.py", line 182, in raise_
    raise exception
  File "d:\ti\python\workspace\microblog\microblog_env\lib\site-packages\sqlalchemy\orm\session.py", line 2642, in _flush
    flush_context.execute()
  File "d:\ti\python\workspace\microblog\microblog_env\lib\site-packages\sqlalchemy\orm\unitofwork.py", line 422, in execute
    rec.execute(self)
  File "d:\ti\python\workspace\microblog\microblog_env\lib\site-packages\sqlalchemy\orm\unitofwork.py", line 586, in execute
    persistence.save_obj(
  File "d:\ti\python\workspace\microblog\microblog_env\lib\site-packages\sqlalchemy\orm\persistence.py", line 230, in save_obj
    _emit_update_statements(
  File "d:\ti\python\workspace\microblog\microblog_env\lib\site-packages\sqlalchemy\orm\persistence.py", line 994, in _emit_update_statements
    c = cached_connections[connection].execute(
  File "d:\ti\python\workspace\microblog\microblog_env\lib\site-packages\sqlalchemy\engine\base.py", line 1011, in execute
    return meth(self, multiparams, params)
  File "d:\ti\python\workspace\microblog\microblog_env\lib\site-packages\sqlalchemy\sql\elements.py", line 298, in _execute_on_connection
    return connection._execute_clauseelement(self, multiparams, params)
  File "d:\ti\python\workspace\microblog\microblog_env\lib\site-packages\sqlalchemy\engine\base.py", line 1124, in _execute_clauseelement
    ret = self._execute_context(
  File "d:\ti\python\workspace\microblog\microblog_env\lib\site-packages\sqlalchemy\engine\base.py", line 1316, in _execute_context
    self._handle_dbapi_exception(
  File "d:\ti\python\workspace\microblog\microblog_env\lib\site-packages\sqlalchemy\engine\base.py", line 1510, in _handle_dbapi_exception
    util.raise_(
  File "d:\ti\python\workspace\microblog\microblog_env\lib\site-packages\sqlalchemy\util\compat.py", line 182, in raise_
    raise exception
  File "d:\ti\python\workspace\microblog\microblog_env\lib\site-packages\sqlalchemy\engine\base.py", line 1276, in _execute_context
    self.dialect.do_execute(
  File "d:\ti\python\workspace\microblog\microblog_env\lib\site-packages\sqlalchemy\engine\default.py", line 609, in do_execute
    cursor.execute(statement, parameters)
sqlalchemy.exc.IntegrityError: (sqlite3.IntegrityError) UNIQUE constraint failed: user.username
[SQL: UPDATE user SET username=? WHERE user.id = ?]
[parameters: ('pedro', 3)]
(Background on this error at: http://sqlalche.me/e/13/gkpj)
2021-01-18 09:14:51,349 INFO: Microblog startup [in D:\TI\Python\Workspace\microblog\app\__init__.py:47]
2021-01-18 14:51:27,142 INFO: Microblog startup [in D:\TI\Python\Workspace\microblog\app\__init__.py:47]
2021-01-18 14:54:01,836 INFO: Microblog startup [in D:\TI\Python\Workspace\microblog\app\__init__.py:47]
2021-01-18 14:54:42,136 INFO: Microblog startup [in D:\TI\Python\Workspace\microblog\app\__init__.py:47]
